Workbook
Name Slicer_Country: #N/A

Sheet Dashboard

Sheet marketing_data _ JGM review
A1: ID | B1: Year_Birth | C1: Approx_Age | D1: Education | E1: Education_mod | F1: Marital_Status | G1: Marital_Status_mod | H1: Marital_binary | I1: Income | J1: Income_mod2 | K1: Kidhome | L1: Teenhome | M1: Total_Children | N1: Dt_Customer | O1: EnrollmentYears | P1: DataSetDate | Q1: Recency | R1: MntWines | S1: MntFruits | T1: MntMeatProducts | U1: MntFishProducts | V1: MntSweetProducts | W1: MntGoldProds | X1: NumDealsPurchases | Y1: NumWebPurchases | Z1: WebPurchGroup | AA1: Web_jitter | AB1: NumCatalogPurchases | AC1: NumStorePurchases | AD1: Store_jitter | AE1: NumWebVisitsMonth | AF1: AcceptedCmp1 | AG1: AcceptedCmp2 | AH1: AcceptedCmp3 | AI1: AcceptedCmp4 | AJ1: AcceptedCmp5 | AK1: Response | AL1: Complain | AM1: Country
A2: 1503 | B2: 1976 | C2: =2021-Table1[[#This Row],[Year_Birth]] -> 45 | D2: PhD | E2: {=_xlfn.SWITCH(Table1[[#This Row],[Education]],"Graduation","Bachelor’s","Basic","High School","2n Cycle","Master’s","Master","Master’s","PhD","PhD","Other")} -> PhD | F2: Together | G2: Together | H2: {=_xlfn.SWITCH(Table1[[#This Row],[Marital_Status_mod]],"Together","Couple","Married","Couple","Divorced","Single","Single","Single","Widow","Single","Other")} -> Couple | I2: 162397 | J2: =IF(I2<10000, "Up to $10K", IF(I2>=100000, "$100K and up", "$" & FLOOR(I2,10000)/1000 & " - $" & FLOOR(I2,10000)/1000+10 & "K")) -> $100K and up | K2: 1 | L2: 1 | M2: =Table1[[#This Row],[Teenhome]]+Table1[[#This Row],[Kidhome]] -> 2 | N2: 41428 | O2: =(Table1[[#This Row],[DataSetDate]]-Table1[[#This Row],[Dt_Customer]])/365 -> 7.6821918 | P2: 44232 | Q2: 31 | R2: 85 | S2: 1 | T2: 16 | U2: 2 | V2: 1 | W2: 2 | X2: 0 | Y2: 0 | Z2: =IF(Y2>=7,"High",IF(Y2>=3,"Medium","Low")) -> Low | AA2: =Y2 + (RAND() - 0.5) * 0.8 -> -0.19892947 | AB2: 0 | AC2: 1 | AD2: =AC2 + (RAND() - 0.5) * 0.8 -> 1.0524438 | AE2: 1 | AF2: 0 | AG2: 0 | AH2: 0 | AI2: 0 | AJ2: 0 | AK2: 0 | AL2: 0 | AM2: Spain
A3: 1501 | B3: 1982 | C3: =2021-Table1[[#This Row],[Year_Birth]] -> 39 | D3: PhD | E3: {=_xlfn.SWITCH(Table1[[#This Row],[Education]],"Graduation","Bachelor’s","Basic","High School","2n Cycle","Master’s","Master","Master’s","PhD","PhD","Other")} -> PhD | F3: Married | G3: Married | H3: {=_xlfn.SWITCH(Table1[[#This Row],[Marital_Status_mod]],"Together","Couple","Married","Couple","Divorced","Single","Single","Single","Widow","Single","Other")} -> Couple | I3: 160803 | J3: =IF(I3<10000, "Up to $10K", IF(I3>=100000, "$100K and up", "$" & FLOOR(I3,10000)/1000 & " - $" & FLOOR(I3,10000)/1000+10 & "K")) -> $100K and up | K3: 0 | L3: 0 | M3: =Table1[[#This Row],[Teenhome]]+Table1[[#This Row],[Kidhome]] -> 0 | N3: 41125 | O3: =(Table1[[#This Row],[DataSetDate]]-Table1[[#This Row],[Dt_Customer]])/365 -> 8.5123288 | P3: 44232 | Q3: 21 | R3: 55 | S3: 16 | T3: 1622 | U3: 17 | V3: 3 | W3: 4 | X3: 15 | Y3: 0 | Z3: =IF(Y3>=7,"High",IF(Y3>=3,"Medium","Low")) -> Low | AA3: =Y3 + (RAND() - 0.5) * 0.8 -> -0.064401305 | AB3: 28 | AC3: 1 | AD3: =AC3 + (RAND() - 0.5) * 0.8 -> 1.0486292 | AE3: 0 | AF3: 0 | AG3: 0 | AH3: 0 | AI3: 0 | AJ3: 0 | AK3: 0 | AL3: 0 | AM3: USA
A4: 5336 | B4: 1971 | C4: =2021-Table1[[#This Row],[Year_Birth]] -> 50 | D4: Master | E4: {=_xlfn.SWITCH(Table1[[#This Row],[Education]],"Graduation","Bachelor’s","Basic","High School","2n Cycle","Master’s","Master","Master’s","PhD","PhD","Other")} -> Master’s | F4: Together | G4: Together | H4: {=_xlfn.SWITCH(Table1[[#This Row],[Marital_Status_mod]],"Together","Couple","Married","Couple","Divorced","Single","Single","Single","Widow","Single","Other")} -> Couple | I4: 157733 | J4: =IF(I4<10000, "Up to $10K", IF(I4>=100000, "$100K and up", "$" & FLOOR(I4,10000)/1000 & " - $" & FLOOR(I4,10000)/1000+10 & "K")) -> $100K and up | K4: 1 | L4: 0 | M4: =Table1[[#This Row],[Teenhome]]+Table1[[#This Row],[Kidhome]] -> 1 | N4: 41429 | O4: =(Table1[[#This Row],[DataSetDate]]-Table1[[#This Row],[Dt_Customer]])/365 -> 7.6794521 | P4: 44232 | Q4: 37 | R4: 39 | S4: 1 | T4: 9 | U4: 2 | V4: 0 | W4: 8 | X4: 0 | Y4: 1 | Z4: =IF(Y4>=7,"High",IF(Y4>=3,"Medium","Low")) -> Low | AA4: =Y4 + (RAND() - 0.5) * 0.8 -> 1.3256471 | AB4: 0 | AC4: 1 | AD4: =AC4 + (RAND() - 0.5) * 0.8 -> 1.1806876 | AE4: 1 | AF4: 0 | AG4: 0 | AH4: 0 | AI4: 0 | AJ4: 0 | AK4: 0 | AL4: 0 | AM4: Spain
A5: 8475 | B5: 1973 | C5: =2021-Table1[[#This Row],[Year_Birth]] -> 48 | D5: PhD | E5: {=_xlfn.SWITCH(Table1[[#This Row],[Education]],"Graduation","Bachelor’s","Basic","High School","2n Cycle","Master’s","Master","Master’s","PhD","PhD","Other")} -> PhD | F5: Married | G5: Married | H5: {=_xlfn.SWITCH(Table1[[#This Row],[Marital_Status_mod]],"Together","Couple","Married","Couple","Divorced","Single","Single","Single","Widow","Single","Other")} -> Couple | I5: 157243 | J5: =IF(I5<10000, "Up to $10K", IF(I5>=100000, "$100K and up", "$" & FLOOR(I5,10000)/1000 & " - $" & FLOOR(I5,10000)/1000+10 & "K")) -> $100K and up | K5: 0 | L5: 1 | M5: =Table1[[#This Row],[Teenhome]]+Table1[[#This Row],[Kidhome]] -> 1 | N5: 41699 | O5: =(Table1[[#This Row],[DataSetDate]]-Table1[[#This Row],[Dt_Customer]])/365 -> 6.939726 | P5: 44232 | Q5: 98 | R5: 20 | S5: 2 | T5: 1582 | U5: 1 | V5: 2 | W5: 1 | X5: 15 | Y5: 0 | Z5: =IF(Y5>=7,"High",IF(Y5>=3,"Medium","Low")) -> Low | AA5: =Y5 + (RAND() - 0.5) * 0.8 -> -0.36954881 | AB5: 22 | AC5: 0 | AD5: =AC5 + (RAND() - 0.5) * 0.8 -> 0.2845029 | AE5: 0 | AF5: 0 | AG5: 0 | AH5: 0 | AI5: 0 | AJ5: 0 | AK5: 0 | AL5: 0 | AM5: India
A6: 4931 | B6: 1977 | C6: =2021-Table1[[#This Row],[Year_Birth]] -> 44 | D6: Graduation | E6: {=_xlfn.SWITCH(Table1[[#This Row],[Education]],"Graduation","Bachelor’s","Basic","High School","2n Cycle","Master’s","Master","Master’s","PhD","PhD","Other")} -> Bachelor’s | F6: Together | G6: Together | H6: {=_xlfn.SWITCH(Table1[[#This Row],[Marital_Status_mod]],"Together","Couple","Married","Couple","Divorced","Single","Single","Single","Widow","Single","Other")} -> Couple | I6: 157146 | J6: =IF(I6<10000, "Up to $10K", IF(I6>=100000, "$100K and up", "$" & FLOOR(I6,10000)/1000 & " - $" & FLOOR(I6,10000)/1000+10 & "K")) -> $100K and up | K6: 0 | L6: 0 | M6: =Table1[[#This Row],[Teenhome]]+Table1[[#This Row],[Kidhome]] -> 0 | N6: 41393 | O6: =(Table1[[#This Row],[DataSetDate]]-Table1[[#This Row],[Dt_Customer]])/365 -> 7.7780822 | P6: 44232 | Q6: 13 | R6: 1 | S6: 0 | T6: 1725 | U6: 2 | V6: 1 | W6: 1 | X6: 0 | Y6: 0 | Z6: =IF(Y6>=7,"High",IF(Y6>=3,"Medium","Low")) -> Low | AA6: =Y6 + (RAND() - 0.5) * 0.8 -> -0.37063109 | AB6: 28 | AC6: 0 | AD6: =AC6 + (RAND() - 0.5) * 0.8 -> -0.11406868 | AE6: 1 | AF6: 0 | AG6: 0 | AH6: 0 | AI6: 0 | AJ6: 0 | AK6: 0 | AL6: 0 | AM6: Saudi Arabia
A7: 11181 | B7: 1949 | C7: =2021-Table1[[#This Row],[Year_Birth]] -> 72 | D7: PhD | E7: {=_xlfn.SWITCH(Table1[[#This Row],[Education]],"Graduation","Bachelor’s","Basic","High School","2n Cycle","Master’s","Master","Master’s","PhD","PhD","Other")} -> PhD | F7: Married | G7: Married | H7: {=_xlfn.SWITCH(Table1[[#This Row],[Marital_Status_mod]],"Together","Couple","Married","Couple","Divorced","Single","Single","Single","Widow","Single","Other")} -> Couple | I7: 156924 | J7: =IF(I7<10000, "Up to $10K", IF(I7>=100000, "$100K and up", "$" & FLOOR(I7,10000)/1000 & " - $" & FLOOR(I7,10000)/1000+10 & "K")) -> $100K and up | K7: 0 | L7: 0 | M7: =Table1[[#This Row],[Teenhome]]+Table1[[#This Row],[Kidhome]] -> 0 | N7: 41515 | O7: =(Table1[[#This Row],[DataSetDate]]-Table1[[#This Row],[Dt_Customer]])/365 -> 7.4438356 | P7: 44232 | Q7: 85 | R7: 2 | S7: 1 | T7: 2 | U7: 1 | V7: 1 | W7: 1 | X7: 0 | Y7: 0 | Z7: =IF(Y7>=7,"High",IF(Y7>=3,"Medium","Low")) -> Low | AA7: =Y7 + (RAND() - 0.5) * 0.8 -> 0.35768688 | AB7: 0 | AC7: 0 | AD7: =AC7 + (RAND() - 0.5) * 0.8 -> 0.089512478 | AE7: 0 | AF7: 0 | AG7: 0 | AH7: 0 | AI7: 0 | AJ7: 0 | AK7: 0 | AL7: 0 | AM7: Canada
A8: 5555 | B8: 1975 | C8: =2021-Table1[[#This Row],[Year_Birth]] -> 46 | D8: Graduation | E8: {=_xlfn.SWITCH(Table1[[#This Row],[Education]],"Graduation","Bachelor’s","Basic","High School","2n Cycle","Master’s","Master","Master’s","PhD","PhD","Other")} -> Bachelor’s | F8: Divorced | G8: Divorced | H8: {=_xlfn.SWITCH(Table1[[#This Row],[Marital_Status_mod]],"Together","Couple","Married","Couple","Divorced","Single","Single","Single","Widow","Single","Other")} -> Single | I8: 153924 | J8: =IF(I8<10000, "Up to $10K", IF(I8>=100000, "$100K and up", "$" & FLOOR(I8,10000)/1000 & " - $" & FLOOR(I8,10000)/1000+10 & "K")) -> $100K and up | K8: 0 | L8: 0 | M8: =Table1[[#This Row],[Teenhome]]+Table1[[#This Row],[Kidhome]] -> 0 | N8: 41677 | O8: =(Table1[[#This Row],[DataSetDate]]-Table1[[#This Row],[Dt_Customer]])/365 -> 7 | P8: 44232 | Q8: 81 | R8: 1 | S8: 1 | T8: 1 | U8: 1 | V8: 1 | W8: 1 | X8: 0 | Y8: 0 | Z8: =IF(Y8>=7,"High",IF(Y8>=3,"Medium","Low")) -> Low | AA8: =Y8 + (RAND() - 0.5) * 0.8 -> 0.33242759 | AB8: 0 | AC8: 0 | AD8: =AC8 + (RAND() - 0.5) * 0.8 -> 0.10279853 | AE8: 0 | AF8: 0 | AG8: 0 | AH8: 0 | AI8: 0 | AJ8: 0 | AK8: 0 | AL8: 0 | AM8: Spain
A9: 4619 | B9: 1945 | C9: =2021-Table1[[#This Row],[Year_Birth]] -> 76 | D9: PhD | E9: {=_xlfn.SWITCH(Table1[[#This Row],[Education]],"Graduation","Bachelor’s","Basic","High School","2n Cycle","Master’s","Master","Master’s","PhD","PhD","Other")} -> PhD | F9: Single | G9: Single | H9: {=_xlfn.SWITCH(Table1[[#This Row],[Marital_Status_mod]],"Together","Couple","Married","Couple","Divorced","Single","Single","Single","Widow","Single","Other")} -> Single | I9: 113734 | J9: =IF(I9<10000, "Up to $10K", IF(I9>=100000, "$100K and up", "$" & FLOOR(I9,10000)/1000 & " - $" & FLOOR(I9,10000)/1000+10 & "K")) -> $100K and up | K9: 0 | L9: 0 | M9: =Table1[[#This Row],[Teenhome]]+Table1[[#This Row],[Kidhome]] -> 0 | N9: 41787 | O9: =(Table1[[#This Row],[DataSetDate]]-Table1[[#This Row],[Dt_Customer]])/365 -> 6.6986301 | P9: 44232 | Q9: 9 | R9: 6 | S9: 2 | T9: 3 | U9: 1 | V9: 262 | W9: 3 | X9: 0 | Y9: 27 | Z9: =IF(Y9>=7,"High",IF(Y9>=3,"Medium","Low")) -> High | AA9: =Y9 + (RAND() - 0.5) * 0.8 -> 27.251377 | AB9: 0 | AC9: 0 | AD9: =AC9 + (RAND() - 0.5) * 0.8 -> 0.097523524 | AE9: 1 | AF9: 0 | AG9: 0 | AH9: 0 | AI9: 0 | AJ9: 0 | AK9: 0 | AL9: 0 | AM9: Spain
A10: 4611 | B10: 1970 | C10: =2021-Table1[[#This Row],[Year_Birth]] -> 51 | D10: Graduation | E10: {=_xlfn.SWITCH(Table1[[#This Row],[Education]],"Graduation","Bachelor’s","Basic","High School","2n Cycle","Master’s","Master","Master’s","PhD","PhD","Other")} -> Bachelor’s | F10: Together | G10: Together | H10: {=_xlfn.SWITCH(Table1[[#This Row],[Marital_Status_mod]],"Together","Couple","Married","Couple","Divorced","Single","Single","Single","Widow","Single","Other")} -> Couple | I10: 105471 | J10: =IF(I10<10000, "Up to $10K", IF(I10>=100000, "$100K and up", "$" & FLOOR(I10,10000)/1000 & " - $" & FLOOR(I10,10000)/1000+10 & "K")) -> $100K and up | K10: 0 | L10: 0 | M10: =Table1[[#This Row],[Teenhome]]+Table1[[#This Row],[Kidhome]] -> 0 | N10: 41295 | O10: =(Table1[[#This Row],[DataSetDate]]-Table1[[#This Row],[Dt_Customer]])/365 -> 8.0465753 | P10: 44232 | Q10: 36 | R10: 1009 | S10: 181 | T10: 104 | U10: 202 | V10: 21 | W10: 207 | X10: 0 | Y10: 9 | Z10: =IF(Y10>=7,"High",IF(Y10>=3,"Medium","Low")) -> High | AA10: =Y10 + (RAND() - 0.5) * 0.8 -> 9.1816903 | AB10: 8 | AC10: 13 | AD10: =AC10 + (RAND() - 0.5) * 0.8 -> 12.759347 | AE10: 3 | AF10: 1 | AG10: 0 | AH10: 0 | AI10: 0 | AJ10: 1 | AK10: 1 | AL10: 0 | AM10: Spain
A11: 10089 | B11: 1974 | C11: =2021-Table1[[#This Row],[Year_Birth]] -> 47 | D11: Graduation | E11: {=_xlfn.SWITCH(Table1[[#This Row],[Education]],"Graduation","Bachelor’s","Basic","High School","2n Cycle","Master’s","Master","Master’s","PhD","PhD","Other")} -> Bachelor’s | F11: Divorced | G11: Divorced | H11: {=_xlfn.SWITCH(Table1[[#This Row],[Marital_Status_mod]],"Together","Couple","Married","Couple","Divorced","Single","Single","Single","Widow","Single","Other")} -> Single | I11: 102692 | J11: =IF(I11<10000, "Up to $10K", IF(I11>=100000, "$100K and up", "$" & FLOOR(I11,10000)/1000 & " - $" & FLOOR(I11,10000)/1000+10 & "K")) -> $100K and up | K11: 0 | L11: 0 | M11: =Table1[[#This Row],[Teenhome]]+Table1[[#This Row],[Kidhome]] -> 0 | N11: 41369 | O11: =(Table1[[#This Row],[DataSetDate]]-Table1[[#This Row],[Dt_Customer]])/365 -> 7.8438356 | P11: 44232 | Q11: 5 | R11: 168 | S11: 148 | T11: 444 | U11: 32 | V11: 172 | W11: 148 | X11: 1 | Y11: 6 | Z11: =IF(Y11>=7,"High",IF(Y11>=3,"Medium","Low")) -> Medium | AA11: =Y11 + (RAND() - 0.5) * 0.8 -> 6.3779882 | AB11: 9 | AC11: 13 | AD11: =AC11 + (RAND() - 0.5) * 0.8 -> 13.1087 | AE11: 2 | AF11: 1 | AG11: 1 | AH11: 0 | AI11: 1 | AJ11: 1 | AK11: 1 | AL11: 0 | AM11: Saudi Arabia
A12: 2798 | B12: 1977 | C12: =2021-Table1[[#This Row],[Year_Birth]] -> 44 | D12: PhD | E12: {=_xlfn.SWITCH(Table1[[#This Row],[Education]],"Graduation","Bachelor’s","Basic","High School","2n Cycle","Master’s","Master","Master’s","PhD","PhD","Other")} -> PhD | F12: Together | G12: Together | H12: {=_xlfn.SWITCH(Table1[[#This Row],[Marital_Status_mod]],"Together","Couple","Married","Couple","Divorced","Single","Single","Single","Widow","Single","Other")} -> Couple | I12: 102160 | J12: =IF(I12<10000, "Up to $10K", IF(I12>=100000, "$100K and up", "$" & FLOOR(I12,10000)/1000 & " - $" & FLOOR(I12,10000)/1000+10 & "K")) -> $100K and up | K12: 0 | L12: 0 | M12: =Table1[[#This Row],[Teenhome]]+Table1[[#This Row],[Kidhome]] -> 0 | N12: 41215 | O12: =(Table1[[#This Row],[DataSetDate]]-Table1[[#This Row],[Dt_Customer]])/365 -> 8.2657534 | P12: 44232 | Q12: 54 | R12: 763 | S12: 29 | T12: 138 | U12: 76 | V12: 176 | W12: 58 | X12: 0 | Y12: 7 | Z12: =IF(Y12>=7,"High",IF(Y12>=3,"Medium","Low")) -> High | AA12: =Y12 + (RAND() - 0.5) * 0.8 -> 6.9207332 | AB12: 9 | AC12: 10 | AD12: =AC12 + (RAND() - 0.5) * 0.8 -> 9.9434369 | AE12: 4 | AF12: 1 | AG12: 0 | AH12: 0 | AI12: 1 | AJ12: 1 | AK12: 1 | AL12: 0 | AM12: Saudi Arabia
A13: 7215 | B13: 1983 | C13: =2021-Table1[[#This Row],[Year_Birth]] -> 38 | D13: Graduation | E13: {=_xlfn.SWITCH(Table1[[#This Row],[Education]],"Graduation","Bachelor’s","Basic","High School","2n Cycle","Master’s","Master","Master’s","PhD","PhD","Other")} -> Bachelor’s | F13: Single | G13: Single | H13: {=_xlfn.SWITCH(Table1[[#This Row],[Marital_Status_mod]],"Together","Couple","Married","Couple","Divorced","Single","Single","Single","Widow","Single","Other")} -> Single | I13: 101970 | J13: =IF(I13<10000, "Up to $10K", IF(I13>=100000, "$100K and up", "$" & FLOOR(I13,10000)/1000 & " - $" & FLOOR(I13,10000)/1000+10 & "K")) -> $100K and up | K13: 0 | L13: 0 | M13: =Table1[[#This Row],[Teenhome]]+Table1[[#This Row],[Kidhome]] -> 0 | N13: 41345 | O13: =(Table1[[#This Row],[DataSetDate]]-Table1[[#This Row],[Dt_Customer]])/365 -> 7.909589 | P13: 44232 | Q13: 69 | R13: 722 | S13: 27 | T13: 102 | U13: 44 | V13: 72 | W13: 168 | X13: 0 | Y13: 6 | Z13: =IF(Y13>=7,"High",IF(Y13>=3,"Medium","Low")) -> Medium | AA13: =Y13 + (RAND() - 0.5) * 0.8 -> 5.6379083 | AB13: 8 | AC13: 13 | AD13: =AC13 + (RAND() - 0.5) * 0.8 -> 13.194877 | AE13: 2 | AF13: 1 | AG13: 0 | AH13: 0 | AI13: 1 | AJ13: 1 | AK13: 1 | AL13: 0 | AM13: Canada
... A2216: 6862 | B2216: 1971 | C2216: =2021-Table1[[#This Row],[Year_Birth]] -> 50 | D2216: Graduation | E2216: {=_xlfn.SWITCH(Table1[[#This Row],[Education]],"Graduation","Bachelor’s","Basic","High School","2n Cycle","Master’s","Master","Master’s","PhD","PhD","Other")} -> Bachelor’s | F2216: Divorced | G2216: Divorced | H2216: {=_xlfn.SWITCH(Table1[[#This Row],[Marital_Status_mod]],"Together","Couple","Married","Couple","Divorced","Single","Single","Single","Widow","Single","Other")} -> Single | I2216: 1730 | J2216: =IF(I2216<10000, "Up to $10K", IF(I2216>=100000, "$100K and up", "$" & FLOOR(I2216,10000)/1000 & " - $" & FLOOR(I2216,10000)/1000+10 & "K")) -> Up to $10K | K2216: 0 | L2216: 0 | M2216: =Table1[[#This Row],[Teenhome]]+Table1[[#This Row],[Kidhome]] -> 0 | N2216: 41777 | O2216: =(Table1[[#This Row],[DataSetDate]]-Table1[[#This Row],[Dt_Customer]])/365 -> 6.7260274 | P2216: 44232 | Q2216: 65 | R2216: 1 | S2216: 1 | T2216: 3 | U2216: 1 | V2216: 1 | W2216: 1 | X2216: 15 | Y2216: 0 | Z2216: =IF(Y2216>=7,"High",IF(Y2216>=3,"Medium","Low")) -> Low | AA2216: =Y2216 + (RAND() - 0.5) * 0.8 -> 0.3184906 | AB2216: 0 | AC2216: 0 | AD2216: =AC2216 + (RAND() - 0.5) * 0.8 -> 0.28071732 | AE2216: 20 | AF2216: 0 | AG2216: 0 | AH2216: 0 | AI2216: 0 | AJ2216: 0 | AK2216: 0 | AL2216: 0 | AM2216: Spain

Sheet DB Tables
B3: Row Labels | C3: Count of Approx_Age | J3: Sum of MntFruits | K3: Sum of MntSweetProducts | L3: Sum of MntFishProducts | M3: Sum of MntGoldProds | N3: Sum of MntMeatProducts | O3: Sum of MntWines
B4: 20-29 | C4: 0.012658228 | E4: 20-29 | F4: =GETPIVOTDATA("Approx_Age",$B$3,"Approx_Age",20) -> 0.012658228 | G4: =IF(F4=MAX($F$4:$F$10),F4,"") | J4: 58391 | K4: 59895 | L4: 83397 | M4: 97415 | N4: 370045 | O4: 676074
B5: 30-39 | C5: 0.14195298 | E5: 30-39 | F5: =GETPIVOTDATA("Approx_Age",$B$3,"Approx_Age",30) -> 0.14195298 | G5: =IF(F5=MAX($F$4:$F$10),F5,"")
B6: 40-49 | C6: 0.29294756 | E6: 40-49 | F6: =GETPIVOTDATA("Approx_Age",$B$3,"Approx_Age",40) -> 0.29294756 | G6: =IF(F6=MAX($F$4:$F$10),F6,"") -> 0.29294756 | J6: Fruits | K6: =GETPIVOTDATA("Sum of MntFruits",$J$3) -> 58391 | L6: =IF(K6=MAX($K$6:$K$11),K6,"")
B7: 50-59 | C7: 0.26175407 | E7: 50-59 | F7: =GETPIVOTDATA("Approx_Age",$B$3,"Approx_Age",50) -> 0.26175407 | G7: =IF(F7=MAX($F$4:$F$10),F7,"") | J7: Sweets | K7: =GETPIVOTDATA("Sum of MntSweetProducts",$J$3) -> 59895 | L7: =IF(K7=MAX($K$6:$K$11),K7,"")
B8: 60-69 | C8: 0.21066908 | E8: 60-69 | F8: =GETPIVOTDATA("Approx_Age",$B$3,"Approx_Age",60) -> 0.21066908 | G8: =IF(F8=MAX($F$4:$F$10),F8,"") | J8: Fish | K8: =GETPIVOTDATA("Sum of MntFishProducts",$J$3) -> 83397 | L8: =IF(K8=MAX($K$6:$K$11),K8,"")
B9: 70-79 | C9: 0.079113924 | E9: 70-79 | F9: =GETPIVOTDATA("Approx_Age",$B$3,"Approx_Age",70) -> 0.079113924 | G9: =IF(F9=MAX($F$4:$F$10),F9,"") | J9: Gold | K9: =GETPIVOTDATA("Sum of MntGoldProds",$J$3) -> 97415 | L9: =IF(K9=MAX($K$6:$K$11),K9,"")
B10: 80-89 | C10: 0.00090415913 | E10: 80-89 | F10: =GETPIVOTDATA("Approx_Age",$B$3,"Approx_Age",80) -> 0.00090415913 | G10: =IF(F10=MAX($F$4:$F$10),F10,"") | J10: Meat | K10: =GETPIVOTDATA("Sum of MntMeatProducts",$J$3) -> 370045 | L10: =IF(K10=MAX($K$6:$K$11),K10,"")
B11: Grand Total | C11: 1 | J11: Wines | K11: =GETPIVOTDATA("Sum of MntWines",$J$3) -> 676074 | L11: =IF(K11=MAX($K$6:$K$11),K11,"") -> 676074
B13: Median age: | C13: =MEDIAN(Table1[Approx_Age]) -> 51
B14: Mean age: | C14: =AVERAGE(Table1[Approx_Age]) -> 52.183296
J15: Values
J16: In-Store | K16: 12852
B17: Row Labels | C17: Count of Marital_Status_mod | J17: Online | K17: 9050
B18: Divorced | C18: 0.1049299 | E18: Divorced | F18: =GETPIVOTDATA("Marital_Status_mod",$B$17,"Marital_Status_mod","Divorced") -> 0.1049299 | G18: =IF(F18=MAX($F$18:$F$22),F18,"") | J18: Catalog | K18: 5918
B19: Married | C19: 0.38760742 | E19: Married | F19: =GETPIVOTDATA("Marital_Status_mod",$B$17,"Marital_Status_mod","Married") -> 0.38760742 | G19: =IF(F19=MAX($F$18:$F$22),F19,"") -> 0.38760742 | J19: Deals | K19: 5145
B20: Single | C20: 0.21438263 | E20: Single | F20: =GETPIVOTDATA("Marital_Status_mod",$B$17,"Marital_Status_mod","Single") -> 0.21438263 | G20: =IF(F20=MAX($F$18:$F$22),F20,"")
B21: Together | C21: 0.25870647 | E21: Together | F21: =GETPIVOTDATA("Marital_Status_mod",$B$17,"Marital_Status_mod","Together") -> 0.25870647 | G21: =IF(F21=MAX($F$18:$F$22),F21,"")
B22: Widow | C22: 0.034373587 | E22: Widow | F22: =GETPIVOTDATA("Marital_Status_mod",$B$17,"Marital_Status_mod","Widow") -> 0.034373587 | G22: =IF(F22=MAX($F$18:$F$22),F22,"")
B23: Grand Total | C23: 1 | J23: Sum of Response | K23: Sum of AcceptedCmp5 | L23: Sum of AcceptedCmp4 | M23: Sum of AcceptedCmp3 | N23: Sum of AcceptedCmp2 | O23: Sum of AcceptedCmp1
J24: 333 | K24: 162 | L24: 164 | M24: 163 | N24: 30 | O24: 142
B26: Row Labels | C26: Count of Country | J26: Campaign Zeta | K26: =GETPIVOTDATA("Sum of Response",$J$23) -> 333 | L26: =IF(K26=MAX($K$26:$K$31),K26,"") -> 333
B27: 0 | C27: 0.28577878 | E27: 0 | F27: =GETPIVOTDATA("Country",$B$26,"Total_Children",0) -> 0.28577878 | G27: =IF(F27=MAX($F$27:$F$30),F27,"") | J27: Campaign Epsilon | K27: =GETPIVOTDATA("Sum of AcceptedCmp5",$J$23) -> 162 | L27: =IF(K27=MAX($K$26:$K$31),K27,"")
B28: 1 | C28: 0.50383747 | E28: 1 | F28: =GETPIVOTDATA("Country",$B$26,"Total_Children",1) -> 0.50383747 | G28: =IF(F28=MAX($F$27:$F$30),F28,"") -> 0.50383747 | J28: Campaign Delta | K28: =GETPIVOTDATA("Sum of AcceptedCmp4",$J$23) -> 164 | L28: =IF(K28=MAX($K$26:$K$31),K28,"")
B29: 2 | C29: 0.18781038 | E29: 2 | F29: =GETPIVOTDATA("Country",$B$26,"Total_Children",2) -> 0.18781038 | G29: =IF(F29=MAX($F$27:$F$30),F29,"") | J29: Campaign Gamma | K29: =GETPIVOTDATA("Sum of AcceptedCmp3",$J$23) -> 163 | L29: =IF(K29=MAX($K$26:$K$31),K29,"")
B30: 3 | C30: 0.022573363 | E30: 3 | F30: =GETPIVOTDATA("Country",$B$26,"Total_Children",3) -> 0.022573363 | G30: =IF(F30=MAX($F$27:$F$30),F30,"") | J30: Campaign Beta | K30: =GETPIVOTDATA("Sum of AcceptedCmp2",$J$23) -> 30 | L30: =IF(K30=MAX($K$26:$K$31),K30,"")
B31: Grand Total | C31: 1 | J31: Campaign Alpha | K31: =GETPIVOTDATA("Sum of AcceptedCmp1",$J$23) -> 142 | L31: =IF(K31=MAX($K$26:$K$31),K31,"")
K32: =SUM(K26:K31) -> 994
B34: Row Labels | C34: Count of Income_mod2
B35: Up to $10K | C35: 0.013092551 | E35: Up to $10K | F35: =GETPIVOTDATA("Income_mod2",$B$34,"Income_mod2","Up to $10K") -> 0.013092551 | G35: =IF(F35=MAX($F$35:$F$45),F35,"") | J35: Row Labels | K35: Sum of NumWebPurchases
B36: $10 - $20K | C36: 0.044243792 | E36: $10 - $20K | F36: =GETPIVOTDATA("Income_mod2",$B$34,"Income_mod2","$10 - $20K") -> 0.044243792 | G36: =IF(F36=MAX($F$35:$F$45),F36,"") | J36: Up to $10K | K36: 89
B37: $20 - $30K | C37: 0.10970655 | E37: $20 - $30K | F37: =GETPIVOTDATA("Income_mod2",$B$34,"Income_mod2","$20 - $30K") -> 0.10970655 | G37: =IF(F37=MAX($F$35:$F$45),F37,"") | J37: $10 - $20K | K37: 173
B38: $30 - $40K | C38: 0.16343115 | E38: $30 - $40K | F38: =GETPIVOTDATA("Income_mod2",$B$34,"Income_mod2","$30 - $40K") -> 0.16343115 | G38: =IF(F38=MAX($F$35:$F$45),F38,"") -> 0.16343115 | J38: $20 - $30K | K38: 461
B39: $40 - $50K | C39: 0.14808126 | E39: $40 - $50K | F39: =GETPIVOTDATA("Income_mod2",$B$34,"Income_mod2","$40 - $50K") -> 0.14808126 | G39: =IF(F39=MAX($F$35:$F$45),F39,"") | J39: $30 - $40K | K39: 848
B40: $50 - $60K | C40: 0.14176072 | E40: $50 - $60K | F40: =GETPIVOTDATA("Income_mod2",$B$34,"Income_mod2","$50 - $60K") -> 0.14176072 | G40: =IF(F40=MAX($F$35:$F$45),F40,"") | J40: $40 - $50K | K40: 1208
B41: $60 - $70K | C41: 0.15079007 | E41: $60 - $70K | F41: =GETPIVOTDATA("Income_mod2",$B$34,"Income_mod2","$60 - $70K") -> 0.15079007 | G41: =IF(F41=MAX($F$35:$F$45),F41,"") | J41: $50 - $60K | K41: 1635
B42: $70 - $80K | C42: 0.13137698 | E42: $70 - $80K | F42: =GETPIVOTDATA("Income_mod2",$B$34,"Income_mod2","$70 - $80K") -> 0.13137698 | G42: =IF(F42=MAX($F$35:$F$45),F42,"") | J42: $60 - $70K | K42: 1970
B43: $80 - $90K | C43: 0.073589165 | E43: $80 - $90K | F43: =GETPIVOTDATA("Income_mod2",$B$34,"Income_mod2","$80 - $90K") -> 0.073589165 | G43: =IF(F43=MAX($F$35:$F$45),F43,"") | J43: $70 - $80K | K43: 1568
B44: $90 - $100K | C44: 0.018510158 | E44: $90 - $100K | F44: =GETPIVOTDATA("Income_mod2",$B$34,"Income_mod2","$90 - $100K") -> 0.018510158 | G44: =IF(F44=MAX($F$35:$F$45),F44,"") | J44: $80 - $90K | K44: 827
B45: $100K and up | C45: 0.0054176072 | E45: $100K and up | F45: =GETPIVOTDATA("Income_mod2",$B$34,"Income_mod2","$100K and up") -> 0.0054176072 | G45: =IF(F45=MAX($F$35:$F$45),F45,"") | J45: $90 - $100K | K45: 215
...

Sheet removed rows
A1: ID | B1: Year_Birth | C1: Approx_Age | D1: Education | E1: Education_mod | F1: Marital_Status | G1: Marital_Status_mod | H1: Marital_binary | I1: Income | J1: Income_mod2 | K1: Kidhome | L1: Teenhome | M1: Total_Children | N1: Dt_Customer | O1: EnrollmentYears | P1: DataSetDate | Q1: Recency | R1: MntWines | S1: MntFruits | T1: MntMeatProducts | U1: MntFishProducts | V1: MntSweetProducts | W1: MntGoldProds | X1: NumDealsPurchases | Y1: NumWebPurchases | Z1: WebPurchGroup | AA1: Web_jitter | AB1: NumCatalogPurchases | AC1: NumStorePurchases | AD1: Store_jitter | AE1: NumWebVisitsMonth | AF1: AcceptedCmp1 | AG1: AcceptedCmp2 | AH1: AcceptedCmp3 | AI1: AcceptedCmp4 | AJ1: AcceptedCmp5 | AK1: Response | AL1: Complain | AM1: Country
A2: 9432 | B2: 1977 | C2: 44 | D2: Graduation | E2: Bachelor’s | F2: Together | G2: Together | H2: Couple | I2: 666666 | J2: $100K and up | K2: 1 | L2: 0 | M2: 1 | N2: 41427 | O2: 7.6849315 | P2: 44232 | Q2: 23 | R2: 9 | S2: 14 | T2: 18 | U2: 8 | V2: 1 | W2: 12 | X2: 4 | Y2: 3 | Z2: Medium | AA2: 2.8072656 | AB2: 1 | AC2: 3 | AD2: 2.7269098 | AE2: 6 | AF2: 0 | AG2: 0 | AH2: 0 | AI2: 0 | AJ2: 0 | AK2: 0 | AL2: 0 | AM2: Saudi Arabia
A4: 2437 | B4: 1989 | C4: 32 | D4: Graduation | E4: Bachelor’s | F4: Married | G4: Married | H4: Couple | K4: 0 | L4: 0 | M4: 0 | N4: 41428 | O4: 7.6821918 | P4: 44232 | Q4: 69 | R4: 861 | S4: 138 | T4: 461 | U4: 60 | V4: 30 | W4: 61 | X4: 1 | Y4: 6 | Z4: Medium | AA4: 6.1099213 | AB4: 5 | AC4: 12 | AD4: 11.944876 | AE4: 3 | AF4: 1 | AG4: 0 | AH4: 0 | AI4: 1 | AJ4: 0 | AK4: 0 | AL4: 0 | AM4: Spain
A5: 2863 | B5: 1970 | C5: 51 | D5: Graduation | E5: Bachelor’s | F5: Single | G5: Single | H5: Single | K5: 1 | L5: 2 | M5: 3 | N5: 41509 | O5: 7.460274 | P5: 44232 | Q5: 67 | R5: 738 | S5: 20 | T5: 172 | U5: 52 | V5: 50 | W5: 20 | X5: 6 | Y5: 2 | Z5: Low | AA5: 2.3737647 | AB5: 3 | AC5: 10 | AD5: 10.221644 | AE5: 7 | AF5: 1 | AG5: 0 | AH5: 0 | AI5: 1 | AJ5: 0 | AK5: 0 | AL5: 0 | AM5: Spain
A6: 5250 | B6: 1943 | C6: 78 | D6: Master | E6: Master’s | F6: Widow | G6: Widow | H6: Single | K6: 0 | L6: 0 | M6: 0 | N6: 41577 | O6: 7.2739726 | P6: 44232 | Q6: 75 | R6: 532 | S6: 126 | T6: 490 | U6: 164 | V6: 126 | W6: 126 | X6: 1 | Y6: 5 | Z6: Medium | AA6: 5.3228651 | AB6: 5 | AC6: 11 | AD6: 10.689453 | AE6: 1 | AF6: 0 | AG6: 0 | AH6: 0 | AI6: 0 | AJ6: 1 | AK6: 1 | AL6: 0 | AM6: Australia
A7: 5798 | B7: 1973 | C7: 48 | D7: Master | E7: Master’s | F7: Together | G7: Together | H7: Couple | K7: 0 | L7: 0 | M7: 0 | N7: 41601 | O7: 7.2082192 | P7: 44232 | Q7: 87 | R7: 445 | S7: 37 | T7: 359 | U7: 98 | V7: 28 | W7: 18 | X7: 1 | Y7: 2 | Z7: Low | AA7: 2.1188102 | AB7: 4 | AC7: 8 | AD7: 7.7911253 | AE7: 1 | AF7: 0 | AG7: 0 | AH7: 0 | AI7: 0 | AJ7: 0 | AK7: 0 | AL7: 0 | AM7: Germany
A8: 7187 | B8: 1969 | C8: 52 | D8: Master | E8: Master’s | F8: Together | G8: Together | H8: Couple | K8: 1 | L8: 1 | M8: 2 | N8: 41412 | O8: 7.7260274 | P8: 44232 | Q8: 52 | R8: 375 | S8: 42 | T8: 48 | U8: 94 | V8: 66 | W8: 96 | X8: 7 | Y8: 4 | Z8: Medium | AA8: 3.9881957 | AB8: 10 | AC8: 4 | AD8: 4.2774504 | AE8: 3 | AF8: 0 | AG8: 0 | AH8: 0 | AI8: 0 | AJ8: 0 | AK8: 0 | AL8: 0 | AM8: Australia
A9: 8268 | B9: 1961 | C9: 60 | D9: PhD | E9: PhD | F9: Married | G9: Married | H9: Couple | K9: 0 | L9: 1 | M9: 1 | N9: 41466 | O9: 7.5780822 | P9: 44232 | Q9: 23 | R9: 352 | S9: 0 | T9: 27 | U9: 10 | V9: 0 | W9: 15 | X9: 3 | Y9: 6 | Z9: Medium | AA9: 6.3019263 | AB9: 1 | AC9: 7 | AD9: 7.2774792 | AE9: 6 | AF9: 0 | AG9: 0 | AH9: 0 | AI9: 0 | AJ9: 0 | AK9: 0 | AL9: 0 | AM9: Canada
A10: 3117 | B10: 1955 | C10: 66 | D10: Graduation | E10: Bachelor’s | F10: Single | G10: Single | H10: Single | K10: 0 | L10: 1 | M10: 1 | N10: 41565 | O10: 7.3068493 | P10: 44232 | Q10: 95 | R10: 264 | S10: 0 | T10: 21 | U10: 12 | V10: 6 | W10: 147 | X10: 3 | Y10: 6 | Z10: Medium | AA10: 5.8680523 | AB10: 1 | AC10: 5 | AD10: 4.6999766 | AE10: 7 | AF10: 0 | AG10: 0 | AH10: 0 | AI10: 0 | AJ10: 0 | AK10: 0 | AL10: 0 | AM10: Australia
A11: 1295 | B11: 1963 | C11: 58 | D11: Graduation | E11: Bachelor’s | F11: Married | G11: Married | H11: Couple | K11: 0 | L11: 1 | M11: 1 | N11: 41497 | O11: 7.4931507 | P11: 44232 | Q11: 96 | R11: 231 | S11: 65 | T11: 196 | U11: 38 | V11: 71 | W11: 124 | X11: 1 | Y11: 6 | Z11: Medium | AA11: 6.2848578 | AB11: 5 | AC11: 7 | AD11: 6.8516908 | AE11: 4 | AF11: 0 | AG11: 0 | AH11: 0 | AI11: 0 | AJ11: 0 | AK11: 0 | AL11: 0 | AM11: Canada
A12: 8996 | B12: 1957 | C12: 64 | D12: PhD | E12: PhD | F12: Married | G12: Married | H12: Couple | K12: 2 | L12: 1 | M12: 3 | N12: 41232 | O12: 8.2191781 | P12: 44232 | Q12: 4 | R12: 230 | S12: 42 | T12: 192 | U12: 49 | V12: 37 | W12: 53 | X12: 12 | Y12: 7 | Z12: High | AA12: 6.8793111 | AB12: 2 | AC12: 8 | AD12: 8.211002 | AE12: 9 | AF12: 0 | AG12: 0 | AH12: 0 | AI12: 0 | AJ12: 0 | AK12: 0 | AL12: 0 | AM12: Germany
A13: 10475 | B13: 1970 | C13: 51 | D13: Master | E13: Master’s | F13: Together | G13: Together | H13: Couple | K13: 0 | L13: 1 | M13: 1 | N13: 41365 | O13: 7.8547945 | P13: 44232 | Q13: 39 | R13: 187 | S13: 5 | T13: 65 | U13: 26 | V13: 20 | W13: 14 | X13: 2 | Y13: 4 | Z13: Medium | AA13: 3.961408 | AB13: 2 | AC13: 6 | AD13: 6.2238573 | AE13: 5 | AF13: 0 | AG13: 0 | AH13: 0 | AI13: 0 | AJ13: 0 | AK13: 0 | AL13: 0 | AM13: USA
A14: 10339 | B14: 1954 | C14: 67 | D14: Master | E14: Master’s | F14: Together | G14: Together | H14: Couple | K14: 0 | L14: 1 | M14: 1 | N14: 41448 | O14: 7.6273973 | P14: 44232 | Q14: 83 | R14: 161 | S14: 0 | T14: 22 | U14: 0 | V14: 0 | W14: 24 | X14: 2 | Y14: 4 | Z14: Medium | AA14: 4.3900059 | AB14: 1 | AC14: 4 | AD14: 4.1937949 | AE14: 6 | AF14: 0 | AG14: 0 | AH14: 0 | AI14: 0 | AJ14: 0 | AK14: 0 | AL14: 0 | AM14: Australia
A15: 7281 | B15: 1959 | C15: 62 | D15: PhD | E15: PhD | F15: Single | G15: Single | H15: Single | K15: 0 | L15: 0 | M15: 0 | N15: 41583 | O15: 7.2575342 | P15: 44232 | Q15: 80 | R15: 81 | S15: 11 | T15: 50 | U15: 3 | V15: 2 | W15: 39 | X15: 1 | Y15: 1 | Z15: Low | AA15: 0.71784506 | AB15: 3 | AC15: 4 | AD15: 3.7797684 | AE15: 2 | AF15: 0 | AG15: 0 | AH15: 0 | AI15: 0 | AJ15: 0 | AK15: 0 | AL15: 0 | AM15: Australia
... A27: 4345 | B27: 1964 | C27: 57 | D27: 2n Cycle | E27: Master’s | F27: Single | G27: Single | H27: Single | K27: 1 | L27: 1 | M27: 2 | N27: 41651 | O27: 7.0712329 | P27: 44232 | Q27: 49 | R27: 5 | S27: 1 | T27: 9 | U27: 2 | V27: 0 | W27: 4 | X27: 1 | Y27: 1 | Z27: Low | AA27: 1.2000039 | AB27: 0 | AC27: 2 | AD27: 2.3669279 | AE27: 7 | AF27: 0 | AG27: 0 | AH27: 0 | AI27: 0 | AJ27: 0 | AK27: 0 | AL27: 0 | AM27: Australia

Sheet Exploratory tables
T1: Income groupings using COUNTIFS and FREQUENCY
E2: Income | H2: Recency of Last Purchase (in days) | T2: 0
B3: Row Labels | C3: Count of Marital_Status | E3: Row Labels | F3: Count of Income | H3: Row Labels | I3: Count of Recency | K3: Sales Totals | T3: 10000 | U3: =COUNTIFS(Table1[Income],"<"&T3,Table1[Income],">"&T2) -> 29
B4: Absurd | C4: 2 | E4: 1730-11729 | F4: 35 | H4: 0-4 | I4: 135 | K4: Wines | L4: =SUM('marketing_data _ JGM review'!R:R) -> 676074 | T4: 20000 | U4: =COUNTIFS(Table1[Income],"<"&T4,Table1[Income],">"&T3) -> 98
B5: Alone | C5: 3 | E5: 11730-21729 | F5: 118 | H5: 5-9 | I5: 97 | K5: Fruits | L5: =SUM('marketing_data _ JGM review'!S:S) -> 58391 | T5: 30000 | U5: =COUNTIFS(Table1[Income],"<"&T5,Table1[Income],">"&T4) -> 243
B6: Divorced | C6: 232 | E6: 21730-31729 | F6: 281 | H6: 10-14 | I6: 121 | K6: Meat | L6: =SUM('marketing_data _ JGM review'!T:T) -> 370045 | T6: 40000 | U6: =COUNTIFS(Table1[Income],"<"&T6,Table1[Income],">"&T5) -> 362
B7: Married | C7: 857 | E7: 31730-41729 | F7: 353 | H7: 15-19 | I7: 99 | K7: Fish | L7: =SUM('marketing_data _ JGM review'!U:U) -> 83397 | T7: 50000 | U7: =COUNTIFS(Table1[Income],"<"&T7,Table1[Income],">"&T6) -> 328
B8: Single | C8: 471 | E8: 41730-51729 | F8: 333 | H8: 20-24 | I8: 109 | K8: Sweets | L8: =SUM('marketing_data _ JGM review'!V:V) -> 59895 | T8: 60000 | U8: =COUNTIFS(Table1[Income],"<"&T8,Table1[Income],">"&T7) -> 314
B9: Together | C9: 572 | E9: 51730-61729 | F9: 305 | H9: 25-29 | I9: 124 | K9: Gold | L9: =SUM('marketing_data _ JGM review'!W:W) -> 97415 | T9: 70000 | U9: =COUNTIFS(Table1[Income],"<"&T9,Table1[Income],">"&T8) -> 333
B10: Widow | C10: 76 | E10: 61730-71729 | F10: 346 | H10: 30-34 | I10: 111 | K10: TOTAL | L10: =SUM(L4:L9) -> 1345217 | T10: 80000 | U10: =COUNTIFS(Table1[Income],"<"&T10,Table1[Income],">"&T9) -> 291
B11: YOLO | C11: 2 | E11: 71730-81729 | F11: 277 | H11: 35-39 | I11: 102 | T11: 90000 | U11: =COUNTIFS(Table1[Income],"<"&T11,Table1[Income],">"&T10) -> 163
B12: Grand Total | C12: 2215 | E12: 81730-91729 | F12: 131 | H12: 40-44 | I12: 91 | K12: Purchase Type Totals | T12: 100000 | U12: =COUNTIFS(Table1[Income],"<"&T12,Table1[Income],">"&T11) -> 40
E13: 91730-101729 | F13: 24 | H13: 45-49 | I13: 123 | K13: w/Discount | L13: =SUM(Table1[NumDealsPurchases]) -> 5145 | T13: Over 100,000 | U13: 13
B14: Row Labels | C14: Count of Education | E14: 101730-111729 | F14: 4 | H14: 50-54 | I14: 122 | K14: via Website | L14: =SUM('marketing_data _ JGM review'!Y:Y) -> 9050
B15: 2n Cycle | C15: 200 | E15: 111730-121729 | F15: 1 | H15: 55-59 | I15: 109 | K15: Catalogue | L15: =SUM('marketing_data _ JGM review'!AB:AB) -> 5918 | T15: 0 | U15: {=FREQUENCY(Table1[Income],'Exploratory tables'!T15:T25)} -> 0
B16: Basic | C16: 54 | E16: 151730-161729 | F16: 6 | H16: 60-64 | I16: 108 | K16: In Stores | L16: =SUM('marketing_data _ JGM review'!AC:AC) -> 12852 | T16: 10000 | U16: 29 | V16: Up to $10K | W16: =U16/SUM($U$16:$U$26) -> 0.013092551
B17: Graduation | C17: 1115 | E17: 161730-171729 | F17: 1 | H17: 65-69 | I17: 103 | T17: 20000 | U17: 98 | V17: 10K to 20K | W17: =U17/SUM($U$16:$U$26) -> 0.044243792
B18: Master | C18: 365 | E18: Grand Total | F18: 2215 | H18: 70-74 | I18: 120 | K18: Campaign Acceptances | T18: 30000 | U18: 243 | V18: 20K to 30K | W18: =U18/SUM($U$16:$U$26) -> 0.10970655
B19: PhD | C19: 481 | G19: 24 blank | H19: 75-79 | I19: 103 | K19: 1st | L19: =SUM('marketing_data _ JGM review'!AF:AF) -> 142 | M19: =L19/$L$25 -> 0.14285714 | T19: 40000 | U19: 362 | V19: 30K to 40K | W19: =U19/SUM($U$16:$U$26) -> 0.16343115
B20: Grand Total | C20: 2215 | E20: Mean income: | F20: =AVERAGE('marketing_data _ JGM review'!I:I) -> 51969.861 | H20: 80-84 | I20: 118 | K20: 2nd | L20: =SUM(Table1[AcceptedCmp2]) -> 30 | M20: =L20/$L$25 -> 0.030181087 | T20: 50000 | U20: 328 | V20: 40K to 50K | W20: =U20/SUM($U$16:$U$26) -> 0.14808126
E21: Income median: | F21: =MEDIAN(Table1[Income]) -> 51373 | H21: 85-89 | I21: 105 | K21: 3rd | L21: =SUM('marketing_data _ JGM review'!AH:AH) -> 163 | M21: =L21/$L$25 -> 0.1639839 | T21: 60000 | U21: 315 | V21: 50K to 60K | W21: =U21/SUM($U$16:$U$26) -> 0.14221219
H22: 90-94 | I22: 115 | K22: 4th | L22: =SUM('marketing_data _ JGM review'!AI:AI) -> 164 | M22: =L22/$L$25 -> 0.16498994 | T22: 70000 | U22: 333 | V22: 60K to 70K | W22: =U22/SUM($U$16:$U$26) -> 0.1503386
H23: 95-100 | I23: 100 | K23: 5th | L23: =SUM('marketing_data _ JGM review'!AJ:AJ) -> 162 | M23: =L23/$L$25 -> 0.16297787 | T23: 80000 | U23: 291 | V23: 70K to 80K | W23: =U23/SUM($U$16:$U$26) -> 0.13137698
H24: Grand Total | I24: 2215 | K24: Last | L24: =SUM(Table1[Response]) -> 333 | M24: =L24/$L$25 -> 0.33501006 | T24: 90000 | U24: 164 | V24: 80K to 90K | W24: =U24/SUM($U$16:$U$26) -> 0.074040632
K25: TOTAL | L25: =SUM(L19:L24) -> 994 | T25: 100000 | U25: 40 | V25: 90K to 100K | W25: =U25/SUM($U$16:$U$26) -> 0.018058691
B26: Length of enrollment | T26: Over 100,000 | U26: 12 | V26: Over 100K | W26: =U26/SUM($U$16:$U$26) -> 0.0054176072
B27: Row Labels | C27: Count of EnrollmentYears
B28: 6-7 | C28: 445
B29: 7-8 | C29: 1155
B30: 8-9 | C30: 615
B31: Grand Total | C31: 2215
B33: Average length of enrollment: | D33: =AVERAGE(Table1[EnrollmentYears]) -> 7.5794626
K34: Row Labels | L34: Discounts | M34: Catalog | N34: Website | O34: Store
B35: Products by Country (with grand total) | K35: Australia | L35: 334 | M35: 397 | N35: 595 | O35: 830
B36: Row Labels | C36: Wine | D36: Fruit | E36: Meat | F36: Fish | G36: Sweets | H36: Gold | I36: Sum of Purchase_total | K36: Canada | L36: 640 | M36: 729 | N36: 1142 | O36: 1554
B37: Spain | C37: 336392 | D37: 28288 | E37: 178409 | F37: 40153 | G37: 30134 | H37: 46181 | I37: 659557 | K37: Germany | L37: 241 | M37: 326 | N37: 464 | O37: 700
B38: Saudi Arabia | C38: 105909 | D38: 8923 | E38: 58380 | F38: 13662 | G38: 9018 | H38: 15117 | I38: 211009 | K38: India | L38: 365 | M38: 365 | N38: 584 | O38: 784
B39: Canada | C39: 84066 | D39: 7681 | E39: 45925 | F39: 9980 | G39: 7607 | H39: 12144 | I39: 167403 | K39: Mexico | L39: 7 | M39: 15 | N39: 18 | O39: 19
B40: Australia | C40: 42752 | D40: 3689 | E40: 22328 | F40: 5546 | G40: 4129 | H40: 7132 | I40: 85576 | K40: Saudi Arabia | L40: 811 | M40: 916 | N40: 1394 | O40: 1985
B41: India | C41: 36236 | D41: 3788 | E41: 23729 | F41: 4818 | G41: 3221 | H41: 6014 | I41: 77806 | K41: Spain | L41: 2462 | M41: 2841 | N41: 4374 | O41: 6330
...

Sheet Unused charts

Sheet Web v various
A2: Web Purchases (Y-axis) v In-Store Purchases (X-axis)
A3: Count of NumWebPurchases | B3: Column Labels | S3: Web purchases by marital status
A4: Row Labels | B4: 0 | C4: 1 | D4: 2 | E4: 3 | F4: 4 | G4: 5 | H4: 6 | I4: 7 | J4: 8 | K4: 9 | L4: 10 | M4: 11 | N4: 12 | O4: 13 | S4: Row Labels | T4: Sum of NumWebPurchases | X4: Row Labels | Y4: Sum of NumWebPurchases
A5: 0 | B5: 10 | C5: 3 | D5: 7 | E5: 28 | S5: Married | T5: 3501 | X5: 1730-11729 | Y5: 101
A6: 1 | B6: 2 | C6: 2 | D6: 142 | E6: 165 | F6: 30 | G6: 3 | H6: 2 | I6: 1 | K6: 1 | S6: Together | T6: 2348 | X6: 11730-21729 | Y6: 210
A7: 2 | D7: 36 | E7: 172 | F7: 91 | G7: 17 | H7: 11 | I7: 4 | J7: 6 | K7: 7 | L7: 6 | M7: 3 | N7: 8 | O7: 7 | S7: Single | T7: 1814 | X7: 21730-31729 | Y7: 529
A8: 3 | D8: 29 | E8: 86 | F8: 65 | G8: 21 | H8: 26 | I8: 22 | J8: 25 | K8: 12 | L8: 18 | M8: 10 | N8: 8 | O8: 11 | S8: Divorced | T8: 1000 | X8: 31730-41729 | Y8: 901
A9: 4 | D9: 3 | E9: 19 | F9: 47 | G9: 41 | H9: 34 | I9: 25 | J9: 30 | K9: 19 | L9: 24 | M9: 13 | N9: 10 | O9: 12 | S9: Widow | T9: 351 | X9: 41730-51729 | Y9: 1308
A10: 5 | D10: 2 | E10: 5 | F10: 31 | G10: 43 | H10: 29 | I10: 18 | J10: 21 | K10: 11 | L10: 17 | M10: 11 | N10: 26 | O10: 5 | S10: Alone | T10: 15 | X10: 51730-61729 | Y10: 1696
A11: 6 | D11: 1 | E11: 2 | F11: 22 | G11: 36 | H11: 20 | I11: 17 | J11: 12 | K11: 16 | L11: 19 | M11: 16 | N11: 19 | O11: 21 | S11: YOLO | T11: 14 | X11: 61730-71729 | Y11: 1982
A12: 7 | E12: 5 | F12: 8 | G12: 21 | H12: 18 | I12: 21 | J12: 17 | K12: 12 | L12: 19 | M12: 9 | N12: 12 | O12: 12 | S12: Absurd | T12: 7 | X12: 71730-81729 | Y12: 1467
A13: 8 | E13: 1 | F13: 12 | G13: 13 | H13: 19 | I13: 16 | J13: 11 | K13: 7 | L13: 6 | M13: 9 | N13: 3 | O13: 5 | X13: 81730-91729 | Y13: 669
A14: 9 | F14: 8 | G14: 8 | H14: 8 | I14: 6 | J14: 9 | K14: 14 | L14: 4 | M14: 3 | N14: 9 | O14: 6 | S14: People in couples: | T14: =SUM(T5:T6) -> 5849 | U14: =TEXT(T14/T15,"0%") & " of singles" -> 184% of singles | X14: 91730-101729 | Y14: 131
A15: 10 | F15: 2 | G15: 4 | H15: 5 | I15: 9 | J15: 6 | K15: 2 | L15: 7 | M15: 1 | N15: 4 | O15: 3 | S15: People solo: | T15: =SUM(T7:T10) -> 3180 | U15: =TEXT(T15/T14,"#%")&" of couples" -> 54% of couples | X15: 101730-111729 | Y15: 28
A16: 11 | F16: 3 | G16: 4 | H16: 5 | I16: 2 | J16: 10 | K16: 5 | L16: 4 | M16: 5 | N16: 5 | O16: 1 | X16: 111730-121729 | Y16: 27
A17: 23 | C17: 1 | X17: 151730-161729 | Y17: 1
A18: 25 | B18: 1 | X18: 161730-171729 | Y18: 0
A19: 27 | B19: 1
S20: Web purchases by education
S21: Row Labels | T21: Sum of NumWebPurchases
S22: Graduation | T22: 4590
S23: PhD | T23: 2132 | AA23: Row Labels | AB23: Sum of NumWebPurchases | AD23: Row Labels | AE23: Sum of NumWebPurchases
S24: Master | T24: 1473 | AA24: Married | AB24: 3501 | AD24: High School | AE24: 0.011270718
S25: 2n Cycle | T25: 753 | AA25: Together | AB25: 2348 | AD25: Bachelor’s | AE25: 0.50718232
S26: Basic | T26: 102 | AA26: Divorced | AB26: 1000 | AD26: Master’s | AE26: 0.24596685
AA27: Single | AB27: 1829 | AD27: PhD | AE27: 0.23558011
AA28: Widow | AB28: 351
S29: Web purchases by education | AA29: Grand Total | AB29: 9029
S30: Graduation | T30: {=SUM(_xlfn._xlws.FILTER(Table1[NumWebPurchases],Table1[Education]='Web v various'!S30))} -> 4590
S31: PhD | T31: {=SUM(_xlfn._xlws.FILTER(Table1[NumWebPurchases],Table1[Education]='Web v various'!S31))} -> 2132
S32: Master | T32: {=SUM(_xlfn._xlws.FILTER(Table1[NumWebPurchases],Table1[Education]='Web v various'!S32))} -> 1473 | AA32: Row Labels | AB32: Sum of NumWebPurchases
S33: 2n Cycle | T33: {=SUM(_xlfn._xlws.FILTER(Table1[NumWebPurchases],Table1[Education]='Web v various'!S33))} -> 753 | AA33: Couple | AB33: 5849
S34: Basic | T34: {=SUM(_xlfn._xlws.FILTER(Table1[NumWebPurchases],Table1[Education]='Web v various'!S34))} -> 102 | AA34: Single | AB34: 3180
AA35: Grand Total | AB35: 9029

Sheet Web v in_store
A1: NumWebPurchases | B1: NumStorePurchases
A2: 3 | B2: 3
A3: 0 | B3: 1
A4: 0 | B4: 1 | D4: SUMMARY OUTPUT
A5: 1 | B5: 1
A6: 0 | B6: 0 | D6: Regression Statistics
A7: 0 | B7: 0 | D7: Multiple R | E7: 0.50271341
A8: 0 | B8: 0 | D8: R Square | E8: 0.25272078
A9: 0 | B9: 0 | D9: Adjusted R Square | E9: 0.25238687
A10: 27 | B10: 0 | D10: Standard Error | E10: 2.4026048
A11: 9 | B11: 13 | D11: Observations | E11: 2240
A12: 6 | B12: 13
A13: 7 | B13: 10 | D13: ANOVA
A14: 6 | B14: 13 | E14: df | F14: SS | G14: MS | H14: F | I14: Significance F
A15: 4 | B15: 9 | D15: Regression | E15: 1 | F15: 4369.0074 | G15: 4369.0074 | H15: 756.86447 | I15: 8.9628024e-144
A16: 4 | B16: 9 | D16: Residual | E16: 2238 | F16: 12918.876 | G16: 5.7725096
A17: 7 | B17: 9 | D17: Total | E17: 2239 | F17: 17287.884
A18: 6 | B18: 10
A19: 7 | B19: 8 | E19: Coefficients | F19: Standard Error | G19: t Stat | H19: P-value | I19: Lower 95% | J19: Upper 95% | K19: Lower 95.0% | L19: Upper 95.0%
A20: 7 | B20: 7 | D20: Intercept | E20: 1.5968527 | F20: 0.10370862 | G20: 15.397493 | H20: 6.3244074e-51 | I20: 1.3934775 | J20: 1.8002278 | K20: 1.3934775 | L20: 1.8002278
A21: 4 | B21: 4 | D21: NumStorePurchases | E21: 0.42968774 | F21: 0.015618665 | G21: 27.51117 | H21: 8.9628024e-144 | I21: 0.39905916 | J21: 0.46031633 | K21: 0.39905916 | L21: 0.46031633
A22: 8 | B22: 4
A23: 5 | B23: 9
A24: 5 | B24: 5
A25: 5 | B25: 5 | D25: RESIDUAL OUTPUT
A26: 5 | B26: 5
A27: 6 | B27: 12 | D27: Observation | E27: Predicted NumWebPurchases | F27: Residuals
A28: 3 | B28: 7 | D28: 1 | E28: 2.8859159 | F28: 0.11408411
A29: 7 | B29: 5 | D29: 2 | E29: 2.0265404 | F29: -2.0265404
A30: 6 | B30: 9 | D30: 3 | E30: 2.0265404 | F30: -2.0265404
A31: 6 | B31: 13 | D31: 4 | E31: 2.0265404 | F31: -1.0265404
A32: 5 | B32: 12 | D32: 5 | E32: 1.5968527 | F32: -1.5968527
A33: 3 | B33: 13 | D33: 6 | E33: 1.5968527 | F33: -1.5968527
A34: 6 | B34: 11 | D34: 7 | E34: 1.5968527 | F34: -1.5968527
A35: 7 | B35: 12 | D35: 8 | E35: 1.5968527 | F35: -1.5968527
A36: 5 | B36: 5 | D36: 9 | E36: 1.5968527 | F36: 25.403147
A37: 5 | B37: 5 | D37: 10 | E37: 7.1827933 | F37: 1.8172067
A38: 5 | B38: 12 | D38: 11 | E38: 7.1827933 | F38: -1.1827933
A39: 9 | B39: 11 | D39: 12 | E39: 5.8937301 | F39: 1.1062699
... A2241: 1 | B2241: 2 | D2241: 2214 | E2241: 1.5968527 | F2241: -1.5968527
...

Sheet Web v in_store 2
B3: Row Labels | C3: Average of NumStorePurchases
B4: Low Use | C4: 3.3599476
B5: Medium Use | C5: 6.7456311
B6: High Use | C6: 7.9263658
B7: Grand Total | C7: 5.8022573

Sheet ProductsPurchased
A1: Attribute | B1: Value | C1: ID
A2: Marital_binary | B2: Couple | C2: 1503 | E2: Row Labels | F2: Sum of Value
A3: MntWines | B3: 85 | C3: 1503 | E3: WebPurchGroup | F3: 0
A4: MntFruits | B4: 1 | C4: 1503 | E4: Marital_binary | F4: 0
A5: MntMeatProducts | B5: 16 | C5: 1503 | E5: Fruit | F5: 58391
A6: MntFishProducts | B6: 2 | C6: 1503 | E6: Sweets | F6: 59895
A7: MntSweetProducts | B7: 1 | C7: 1503 | E7: Fish | F7: 83397
A8: MntGoldProds | B8: 2 | C8: 1503 | E8: Gold | F8: 97415
A9: WebPurchGroup | B9: Low | C9: 1503 | E9: Meat | F9: 370045
A10: Marital_binary | B10: Couple | C10: 1501 | E10: Wine | F10: 676074
A11: MntWines | B11: 55 | C11: 1501 | E11: Grand Total | F11: 1345217
A12: MntFruits | B12: 16 | C12: 1501
A13: MntMeatProducts | B13: 1622 | C13: 1501
A14: MntFishProducts | B14: 17 | C14: 1501
A15: MntSweetProducts | B15: 3 | C15: 1501
A16: MntGoldProds | B16: 4 | C16: 1501
A17: WebPurchGroup | B17: Low | C17: 1501
A18: Marital_binary | B18: Couple | C18: 5336
A19: MntWines | B19: 39 | C19: 5336
A20: MntFruits | B20: 1 | C20: 5336
A21: MntMeatProducts | B21: 9 | C21: 5336
A22: MntFishProducts | B22: 2 | C22: 5336 | E22: I created this using PowerQuery … but then realized that I wouldn't be able to apply my slicer to it
A23: MntSweetProducts | B23: 0 | C23: 5336
A24: MntGoldProds | B24: 8 | C24: 5336
A25: WebPurchGroup | B25: Low | C25: 5336
A26: Marital_binary | B26: Couple | C26: 8475
A27: MntWines | B27: 20 | C27: 8475
A28: MntFruits | B28: 2 | C28: 8475
A29: MntMeatProducts | B29: 1582 | C29: 8475
A30: MntFishProducts | B30: 1 | C30: 8475
A31: MntSweetProducts | B31: 2 | C31: 8475
A32: MntGoldProds | B32: 1 | C32: 8475
A33: WebPurchGroup | B33: Low | C33: 8475
A34: Marital_binary | B34: Couple | C34: 4931
A35: MntWines | B35: 1 | C35: 4931
A36: MntFruits | B36: 0 | C36: 4931
A37: MntMeatProducts | B37: 1725 | C37: 4931
A38: MntFishProducts | B38: 2 | C38: 4931
A39: MntSweetProducts | B39: 1 | C39: 4931
A40: MntGoldProds | B40: 1 | C40: 4931
...

Sheet ProductPurchase2
A1: ID | B1: Country | C1: Attribute | D1: Value
A2: 1503 | B2: Spain | C2: MntWines | D2: 85
A3: 1503 | B3: Spain | C3: MntFruits | D3: 1
A4: 1503 | B4: Spain | C4: MntMeatProducts | D4: 16
A5: 1503 | B5: Spain | C5: MntFishProducts | D5: 2 | F5: Row Labels | G5: Sum of Value
A6: 1503 | B6: Spain | C6: MntSweetProducts | D6: 1 | F6: MntFishProducts | G6: 83397
A7: 1503 | B7: Spain | C7: MntGoldProds | D7: 2 | F7: MntFruits | G7: 58391
A8: 1501 | B8: USA | C8: MntWines | D8: 55 | F8: MntGoldProds | G8: 97415
A9: 1501 | B9: USA | C9: MntFruits | D9: 16 | F9: MntMeatProducts | G9: 370045
A10: 1501 | B10: USA | C10: MntMeatProducts | D10: 1622 | F10: MntSweetProducts | G10: 59895
A11: 1501 | B11: USA | C11: MntFishProducts | D11: 17 | F11: MntWines | G11: 676074
A12: 1501 | B12: USA | C12: MntSweetProducts | D12: 3 | F12: Grand Total | G12: 1345217
A13: 1501 | B13: USA | C13: MntGoldProds | D13: 4
A14: 5336 | B14: Spain | C14: MntWines | D14: 39
A15: 5336 | B15: Spain | C15: MntFruits | D15: 1
A16: 5336 | B16: Spain | C16: MntMeatProducts | D16: 9
A17: 5336 | B17: Spain | C17: MntFishProducts | D17: 2
A18: 5336 | B18: Spain | C18: MntSweetProducts | D18: 0
A19: 5336 | B19: Spain | C19: MntGoldProds | D19: 8
A20: 8475 | B20: India | C20: MntWines | D20: 20
A21: 8475 | B21: India | C21: MntFruits | D21: 2
A22: 8475 | B22: India | C22: MntMeatProducts | D22: 1582
A23: 8475 | B23: India | C23: MntFishProducts | D23: 1
A24: 8475 | B24: India | C24: MntSweetProducts | D24: 2
... A13291: 6862 | B13291: Spain | C13291: MntGoldProds | D13291: 1

Sheet Products by Country
A3: Row Labels | B3: Wine | C3: Meat | D3: Gold | E3: Fish | F3: Sweets | G3: Fruit
A4: Spain | B4: 336392 | C4: 178409 | D4: 46181 | E4: 40153 | F4: 30134 | G4: 28288 | M4: Spain | N4: Saudi Arabia | O4: Canada | P4: Australia | Q4: India | R4: Germany | S4: USA | T4: Mexico | U4: Total | X4: Spain | Y4: Saudi Arabia | Z4: Canada | AA4: Australia | AB4: India | AC4: Germany | AD4: USA | AE4: Mexico | AF4: Total
A5: Saudi Arabia | B5: 105909 | C5: 58380 | D5: 15117 | E5: 13662 | F5: 9018 | G5: 8923 | L5: Wines | M5: {=SUM(_xlfn._xlws.FILTER(Table1[[MntWines]:[MntWines]],Table1[[Country]:[Country]]='Products by Country'!M$4))} -> 336392 | N5: {=SUM(_xlfn._xlws.FILTER(Table1[[MntWines]:[MntWines]],Table1[[Country]:[Country]]='Products by Country'!N$4))} -> 105909 | O5: {=SUM(_xlfn._xlws.FILTER(Table1[[MntWines]:[MntWines]],Table1[[Country]:[Country]]='Products by Country'!O$4))} -> 84066 | P5: {=SUM(_xlfn._xlws.FILTER(Table1[[MntWines]:[MntWines]],Table1[[Country]:[Country]]='Products by Country'!P$4))} -> 42752 | Q5: {=SUM(_xlfn._xlws.FILTER(Table1[[MntWines]:[MntWines]],Table1[[Country]:[Country]]='Products by Country'!Q$4))} -> 36236 | R5: {=SUM(_xlfn._xlws.FILTER(Table1[[MntWines]:[MntWines]],Table1[[Country]:[Country]]='Products by Country'!R$4))} -> 36776 | S5: {=SUM(_xlfn._xlws.FILTER(Table1[[MntWines]:[MntWines]],Table1[[Country]:[Country]]='Products by Country'!S$4))} -> 32214 | T5: {=SUM(_xlfn._xlws.FILTER(Table1[[MntWines]:[MntWines]],Table1[[Country]:[Country]]='Products by Country'!T$4))} -> 1729 | U5: =SUM(M5:T5) -> 676074 | W5: Wines | X5: {=SUM(_xlfn._xlws.FILTER(Table1[[MntWines]:[MntWines]],Table1[[Country]:[Country]]='Products by Country'!X$4))} -> 336392 | Y5: {=SUM(_xlfn._xlws.FILTER(Table1[[MntWines]:[MntWines]],Table1[[Country]:[Country]]='Products by Country'!Y$4))} -> 105909 | Z5: {=SUM(_xlfn._xlws.FILTER(Table1[[MntWines]:[MntWines]],Table1[[Country]:[Country]]='Products by Country'!Z$4))} -> 84066 | AA5: {=SUM(_xlfn._xlws.FILTER(Table1[[MntWines]:[MntWines]],Table1[[Country]:[Country]]='Products by Country'!AA$4))} -> 42752 | AB5: {=SUM(_xlfn._xlws.FILTER(Table1[[MntWines]:[MntWines]],Table1[[Country]:[Country]]='Products by Country'!AB$4))} -> 36236 | AC5: {=SUM(_xlfn._xlws.FILTER(Table1[[MntWines]:[MntWines]],Table1[[Country]:[Country]]='Products by Country'!AC$4))} -> 36776 | AD5: {=SUM(_xlfn._xlws.FILTER(Table1[[MntWines]:[MntWines]],Table1[[Country]:[Country]]='Products by Country'!AD$4))} -> 32214 | AE5: {=SUM(_xlfn._xlws.FILTER(Table1[[MntWines]:[MntWines]],Table1[[Country]:[Country]]='Products by Country'!AE$4))} -> 1729 | AF5: =SUM(X5:AE5) -> 676074
A6: Canada | B6: 84066 | C6: 45925 | D6: 12144 | E6: 9980 | F6: 7607 | G6: 7681 | L6: Fruits | M6: {=SUM(_xlfn._xlws.FILTER(Table1[[MntFruits]:[MntFruits]],Table1[[Country]:[Country]]='Products by Country'!M$4))} -> 28288 | N6: {=SUM(_xlfn._xlws.FILTER(Table1[[MntFruits]:[MntFruits]],Table1[[Country]:[Country]]='Products by Country'!N$4))} -> 8923 | O6: {=SUM(_xlfn._xlws.FILTER(Table1[[MntFruits]:[MntFruits]],Table1[[Country]:[Country]]='Products by Country'!O$4))} -> 7681 | P6: {=SUM(_xlfn._xlws.FILTER(Table1[[MntFruits]:[MntFruits]],Table1[[Country]:[Country]]='Products by Country'!P$4))} -> 3689 | Q6: {=SUM(_xlfn._xlws.FILTER(Table1[[MntFruits]:[MntFruits]],Table1[[Country]:[Country]]='Products by Country'!Q$4))} -> 3788 | R6: {=SUM(_xlfn._xlws.FILTER(Table1[[MntFruits]:[MntFruits]],Table1[[Country]:[Country]]='Products by Country'!R$4))} -> 2980 | S6: {=SUM(_xlfn._xlws.FILTER(Table1[[MntFruits]:[MntFruits]],Table1[[Country]:[Country]]='Products by Country'!S$4))} -> 3034 | T6: {=SUM(_xlfn._xlws.FILTER(Table1[[MntFruits]:[MntFruits]],Table1[[Country]:[Country]]='Products by Country'!T$4))} -> 8 | U6: =SUM(M6:T6) -> 58391 | W6: Fruits | X6: {=SUM(_xlfn._xlws.FILTER(Table1[[MntFruits]:[MntFruits]],Table1[[Country]:[Country]]='Products by Country'!X$4))} -> 28288 | Y6: {=SUM(_xlfn._xlws.FILTER(Table1[[MntFruits]:[MntFruits]],Table1[[Country]:[Country]]='Products by Country'!Y$4))} -> 8923 | Z6: {=SUM(_xlfn._xlws.FILTER(Table1[[MntFruits]:[MntFruits]],Table1[[Country]:[Country]]='Products by Country'!Z$4))} -> 7681 | AA6: {=SUM(_xlfn._xlws.FILTER(Table1[[MntFruits]:[MntFruits]],Table1[[Country]:[Country]]='Products by Country'!AA$4))} -> 3689 | AB6: {=SUM(_xlfn._xlws.FILTER(Table1[[MntFruits]:[MntFruits]],Table1[[Country]:[Country]]='Products by Country'!AB$4))} -> 3788 | AC6: {=SUM(_xlfn._xlws.FILTER(Table1[[MntFruits]:[MntFruits]],Table1[[Country]:[Country]]='Products by Country'!AC$4))} -> 2980 | AD6: {=SUM(_xlfn._xlws.FILTER(Table1[[MntFruits]:[MntFruits]],Table1[[Country]:[Country]]='Products by Country'!AD$4))} -> 3034 | AE6: {=SUM(_xlfn._xlws.FILTER(Table1[[MntFruits]:[MntFruits]],Table1[[Country]:[Country]]='Products by Country'!AE$4))} -> 8 | AF6: =SUM(X6:AE6) -> 58391
A7: Australia | B7: 42752 | C7: 22328 | D7: 7132 | E7: 5546 | F7: 4129 | G7: 3689 | L7: Fish | M7: {=SUM(_xlfn._xlws.FILTER(Table1[[MntFishProducts]:[MntFishProducts]],Table1[[Country]:[Country]]='Products by Country'!M$4))} -> 40153 | N7: {=SUM(_xlfn._xlws.FILTER(Table1[[MntFishProducts]:[MntFishProducts]],Table1[[Country]:[Country]]='Products by Country'!N$4))} -> 13662 | O7: {=SUM(_xlfn._xlws.FILTER(Table1[[MntFishProducts]:[MntFishProducts]],Table1[[Country]:[Country]]='Products by Country'!O$4))} -> 9980 | P7: {=SUM(_xlfn._xlws.FILTER(Table1[[MntFishProducts]:[MntFishProducts]],Table1[[Country]:[Country]]='Products by Country'!P$4))} -> 5546 | Q7: {=SUM(_xlfn._xlws.FILTER(Table1[[MntFishProducts]:[MntFishProducts]],Table1[[Country]:[Country]]='Products by Country'!Q$4))} -> 4818 | R7: {=SUM(_xlfn._xlws.FILTER(Table1[[MntFishProducts]:[MntFishProducts]],Table1[[Country]:[Country]]='Products by Country'!R$4))} -> 4601 | S7: {=SUM(_xlfn._xlws.FILTER(Table1[[MntFishProducts]:[MntFishProducts]],Table1[[Country]:[Country]]='Products by Country'!S$4))} -> 4411 | T7: {=SUM(_xlfn._xlws.FILTER(Table1[[MntFishProducts]:[MntFishProducts]],Table1[[Country]:[Country]]='Products by Country'!T$4))} -> 226 | U7: =SUM(M7:T7) -> 83397 | W7: Fish | X7: {=SUM(_xlfn._xlws.FILTER(Table1[[MntFishProducts]:[MntFishProducts]],Table1[[Country]:[Country]]='Products by Country'!X$4))} -> 40153 | Y7: {=SUM(_xlfn._xlws.FILTER(Table1[[MntFishProducts]:[MntFishProducts]],Table1[[Country]:[Country]]='Products by Country'!Y$4))} -> 13662 | Z7: {=SUM(_xlfn._xlws.FILTER(Table1[[MntFishProducts]:[MntFishProducts]],Table1[[Country]:[Country]]='Products by Country'!Z$4))} -> 9980 | AA7: {=SUM(_xlfn._xlws.FILTER(Table1[[MntFishProducts]:[MntFishProducts]],Table1[[Country]:[Country]]='Products by Country'!AA$4))} -> 5546 | AB7: {=SUM(_xlfn._xlws.FILTER(Table1[[MntFishProducts]:[MntFishProducts]],Table1[[Country]:[Country]]='Products by Country'!AB$4))} -> 4818 | AC7: {=SUM(_xlfn._xlws.FILTER(Table1[[MntFishProducts]:[MntFishProducts]],Table1[[Country]:[Country]]='Products by Country'!AC$4))} -> 4601 | AD7: {=SUM(_xlfn._xlws.FILTER(Table1[[MntFishProducts]:[MntFishProducts]],Table1[[Country]:[Country]]='Products by Country'!AD$4))} -> 4411 | AE7: {=SUM(_xlfn._xlws.FILTER(Table1[[MntFishProducts]:[MntFishProducts]],Table1[[Country]:[Country]]='Products by Country'!AE$4))} -> 226 | AF7: =SUM(X7:AE7) -> 83397
A8: India | B8: 36236 | C8: 23729 | D8: 6014 | E8: 4818 | F8: 3221 | G8: 3788 | L8: Meat | M8: {=SUM(_xlfn._xlws.FILTER(Table1[[MntMeatProducts]:[MntMeatProducts]],Table1[[Country]:[Country]]='Products by Country'!M$4))} -> 178409 | N8: {=SUM(_xlfn._xlws.FILTER(Table1[[MntMeatProducts]:[MntMeatProducts]],Table1[[Country]:[Country]]='Products by Country'!N$4))} -> 58380 | O8: {=SUM(_xlfn._xlws.FILTER(Table1[[MntMeatProducts]:[MntMeatProducts]],Table1[[Country]:[Country]]='Products by Country'!O$4))} -> 45925 | P8: {=SUM(_xlfn._xlws.FILTER(Table1[[MntMeatProducts]:[MntMeatProducts]],Table1[[Country]:[Country]]='Products by Country'!P$4))} -> 22328 | Q8: {=SUM(_xlfn._xlws.FILTER(Table1[[MntMeatProducts]:[MntMeatProducts]],Table1[[Country]:[Country]]='Products by Country'!Q$4))} -> 23729 | R8: {=SUM(_xlfn._xlws.FILTER(Table1[[MntMeatProducts]:[MntMeatProducts]],Table1[[Country]:[Country]]='Products by Country'!R$4))} -> 20272 | S8: {=SUM(_xlfn._xlws.FILTER(Table1[[MntMeatProducts]:[MntMeatProducts]],Table1[[Country]:[Country]]='Products by Country'!S$4))} -> 20185 | T8: {=SUM(_xlfn._xlws.FILTER(Table1[[MntMeatProducts]:[MntMeatProducts]],Table1[[Country]:[Country]]='Products by Country'!T$4))} -> 817 | U8: =SUM(M8:T8) -> 370045 | W8: Meat | X8: {=SUM(_xlfn._xlws.FILTER(Table1[[MntMeatProducts]:[MntMeatProducts]],Table1[[Country]:[Country]]='Products by Country'!X$4))} -> 178409 | Y8: {=SUM(_xlfn._xlws.FILTER(Table1[[MntMeatProducts]:[MntMeatProducts]],Table1[[Country]:[Country]]='Products by Country'!Y$4))} -> 58380 | Z8: {=SUM(_xlfn._xlws.FILTER(Table1[[MntMeatProducts]:[MntMeatProducts]],Table1[[Country]:[Country]]='Products by Country'!Z$4))} -> 45925 | AA8: {=SUM(_xlfn._xlws.FILTER(Table1[[MntMeatProducts]:[MntMeatProducts]],Table1[[Country]:[Country]]='Products by Country'!AA$4))} -> 22328 | AB8: {=SUM(_xlfn._xlws.FILTER(Table1[[MntMeatProducts]:[MntMeatProducts]],Table1[[Country]:[Country]]='Products by Country'!AB$4))} -> 23729 | AC8: {=SUM(_xlfn._xlws.FILTER(Table1[[MntMeatProducts]:[MntMeatProducts]],Table1[[Country]:[Country]]='Products by Country'!AC$4))} -> 20272 | AD8: {=SUM(_xlfn._xlws.FILTER(Table1[[MntMeatProducts]:[MntMeatProducts]],Table1[[Country]:[Country]]='Products by Country'!AD$4))} -> 20185 | AE8: {=SUM(_xlfn._xlws.FILTER(Table1[[MntMeatProducts]:[MntMeatProducts]],Table1[[Country]:[Country]]='Products by Country'!AE$4))} -> 817 | AF8: =SUM(X8:AE8) -> 370045
A9: Germany | B9: 36776 | C9: 20272 | D9: 5768 | E9: 4601 | F9: 2801 | G9: 2980 | L9: Sweets | M9: {=SUM(_xlfn._xlws.FILTER(Table1[[MntSweetProducts]:[MntSweetProducts]],Table1[[Country]:[Country]]='Products by Country'!M$4))} -> 30134 | N9: {=SUM(_xlfn._xlws.FILTER(Table1[[MntSweetProducts]:[MntSweetProducts]],Table1[[Country]:[Country]]='Products by Country'!N$4))} -> 9018 | O9: {=SUM(_xlfn._xlws.FILTER(Table1[[MntSweetProducts]:[MntSweetProducts]],Table1[[Country]:[Country]]='Products by Country'!O$4))} -> 7607 | P9: {=SUM(_xlfn._xlws.FILTER(Table1[[MntSweetProducts]:[MntSweetProducts]],Table1[[Country]:[Country]]='Products by Country'!P$4))} -> 4129 | Q9: {=SUM(_xlfn._xlws.FILTER(Table1[[MntSweetProducts]:[MntSweetProducts]],Table1[[Country]:[Country]]='Products by Country'!Q$4))} -> 3221 | R9: {=SUM(_xlfn._xlws.FILTER(Table1[[MntSweetProducts]:[MntSweetProducts]],Table1[[Country]:[Country]]='Products by Country'!R$4))} -> 2801 | S9: {=SUM(_xlfn._xlws.FILTER(Table1[[MntSweetProducts]:[MntSweetProducts]],Table1[[Country]:[Country]]='Products by Country'!S$4))} -> 2863 | T9: {=SUM(_xlfn._xlws.FILTER(Table1[[MntSweetProducts]:[MntSweetProducts]],Table1[[Country]:[Country]]='Products by Country'!T$4))} -> 122 | U9: =SUM(M9:T9) -> 59895 | W9: Sweets | X9: {=SUM(_xlfn._xlws.FILTER(Table1[[MntSweetProducts]:[MntSweetProducts]],Table1[[Country]:[Country]]='Products by Country'!X$4))} -> 30134 | Y9: {=SUM(_xlfn._xlws.FILTER(Table1[[MntSweetProducts]:[MntSweetProducts]],Table1[[Country]:[Country]]='Products by Country'!Y$4))} -> 9018 | Z9: {=SUM(_xlfn._xlws.FILTER(Table1[[MntSweetProducts]:[MntSweetProducts]],Table1[[Country]:[Country]]='Products by Country'!Z$4))} -> 7607 | AA9: {=SUM(_xlfn._xlws.FILTER(Table1[[MntSweetProducts]:[MntSweetProducts]],Table1[[Country]:[Country]]='Products by Country'!AA$4))} -> 4129 | AB9: {=SUM(_xlfn._xlws.FILTER(Table1[[MntSweetProducts]:[MntSweetProducts]],Table1[[Country]:[Country]]='Products by Country'!AB$4))} -> 3221 | AC9: {=SUM(_xlfn._xlws.FILTER(Table1[[MntSweetProducts]:[MntSweetProducts]],Table1[[Country]:[Country]]='Products by Country'!AC$4))} -> 2801 | AD9: {=SUM(_xlfn._xlws.FILTER(Table1[[MntSweetProducts]:[MntSweetProducts]],Table1[[Country]:[Country]]='Products by Country'!AD$4))} -> 2863 | AE9: {=SUM(_xlfn._xlws.FILTER(Table1[[MntSweetProducts]:[MntSweetProducts]],Table1[[Country]:[Country]]='Products by Country'!AE$4))} -> 122 | AF9: =SUM(X9:AE9) -> 59895
